<?xml version="1.0" encoding="UTF-8"?>
<robot xmlns:xacro="http://ros.org/wiki/xacro">

    <xacro:macro name="default_finger_limits">
        <limit lower="-1.005" upper="0.1" effort="1.5" velocity="0.2" />
    </xacro:macro>


    <xacro:macro name="default_damping_low">
        <dynamics damping="0.05" friction="0.05" />
    </xacro:macro>

    <xacro:macro name="default_damping_medium">
        <dynamics damping="0.5" friction="0.5" />
    </xacro:macro>

    <xacro:macro name="default_damping_high">
        <dynamics damping="0.7" friction="1.0" />
    </xacro:macro>

    <xacro:macro name="damping_fingers">
        <dynamics damping="0.005" friction="0.005" />
    </xacro:macro>

    <!-- Formula according to https://en.wikipedia.org/wiki/List_of_moment_of_inertia_tensors for
    cylinder -->
    <xacro:macro name="cyl_inertia" params="mass r h ">
        <mass value="${mass}" />
        <inertia ixx="${0.083333 * mass * (3*r*r + h*h)}" ixy="0" ixz="0"
            iyy="${0.083333 * mass * (3*r*r + h*h)}" iyz="0"
            izz="${0.5*mass*r*r}" />
    </xacro:macro>

    <xacro:property name="M_PI" value="3.14159265358979" />
    <xacro:property name="M_PI_2" value="1.5707963267949" />
    <xacro:property name="M_PI_4" value="0.785398163" />


    <!-- ***************** MODEL CORRECTIONS ************************* -->

    <xacro:property name="wrist_scale_x" value="1.0" />
    <xacro:property name="wrist_scale_y" value="1.0" />
    <xacro:property name="wrist_scale_z" value="1.0" />

    <xacro:property name="base_height_corr" value="0" />
    <xacro:property name="base_height_corr" value="0" />


    <xacro:property name="tip_scale_x" value="1" />
    <xacro:property name="tip_scale_y" value="1" />
    <xacro:property name="tip_scale_z" value="1" />


    <xacro:property name="f_thb_xyz" value=" 0.0319  0.003  0.11" />
    <xacro:property name="f_idx_xyz" value="-0.0276  0.0204 0.11" />
    <xacro:property name="f_pnk_xyz" value="-0.0276 -0.0204 0.11" />

    <xacro:property name="f_thb_rpy" value="0 -0.37 ${M_PI-0.226892}" />

    <xacro:property name="f_idx_rpy" value="0 -0.34 -0.191986" />
    <xacro:property name="f_pnk_rpy" value="0 -0.34 0.191986" />


    <xacro:property name="f_thb_m_xyz" value=" 0.037  0.001  0.095" />
    <xacro:property name="f_idx_m_xyz" value="-0.034  0.022 0.095" />
    <xacro:property name="f_pnk_m_xyz" value="-0.034 -0.022 0.095" />
    <xacro:property name="f_thb_m_rpy" value="0 -0.2658 ${M_PI-0.226892}" />
    <xacro:property name="f_idx_m_rpy" value="0 -0.2293 -0.191986" />
    <xacro:property name="f_pnk_m_rpy" value="0 -0.2293 0.191986" />


    <!-- MACRO FOR THE ROBOT HAND -->
    <xacro:macro name="jaco_hand"
        params="parent mass_divider activate_gravity floating_gripper finger_mass_divider *origin jaco_prefix:=jaco">

        <!-- ...........................        -->
        <joint name="hand_joint" type="fixed">
            <xacro:insert_block name="origin" />
            <parent link="${parent}" />
            <child link="${jaco_prefix}_6_hand_limb" />
        </joint>


        <link name="${jaco_prefix}_6_hand_limb">
            <inertial>
                <origin xyz="-0.0555917045329114 -7.25586546752172E-05 -0.00317411883668722"
                    rpy="0 0 0" />
                <xacro:cyl_inertia mass="${0.2/mass_divider}" h="0.104" r="0.11" />
            </inertial>
            <visual>
                <origin xyz="0 0 0" rpy="0 0 0" />
                <geometry>
                    <mesh filename="package://manipulacion_pkg/urdf/meshes/jaco_hand/6_hand_limb.STL"
                        scale="${wrist_scale_x} ${wrist_scale_y} ${wrist_scale_z}" />
                </geometry>
                <material name="">
                    <color rgba="0.1 0.1 0.1 1" />
                </material>
            </visual>
            <collision>
                <origin xyz="0 0 0" rpy="0 0 0" />
                <geometry>
                    <mesh filename="package://manipulacion_pkg/urdf/meshes/jaco_hand/6_hand_limb.STL"
                        scale="${wrist_scale_x} ${wrist_scale_y} ${wrist_scale_z}" />
                </geometry>
            </collision>
            <surface>
                <friction>
                  <ode>
                    <mu>1.0</mu> <!-- Static friction coefficient -->
                    <mu2>1.0</mu2> <!-- Dynamic friction coefficient -->
                    <slip1>0.0</slip1> <!-- Slip compliance, set to 0 for no slip -->
                    <slip2>0.0</slip2> <!-- Slip compliance, set to 0 for no slip -->
                  </ode>
                </friction>
              </surface>  
        </link>

        <link name="${jaco_prefix}_fingers_base_link">
            <inertial>
                <origin xyz="0 0 0" rpy="0 0 0" />
                <xacro:cyl_inertia mass="${0.001/mass_divider}" h="0.01" r="0.01" />
            </inertial>
        </link>

        <!-- this joint is only to align the coordinate system with the kinova specification frame -->
        <joint name="${jaco_prefix}_fingers_base_joint" type="fixed">
            <origin xyz="0 0 0" rpy="${-M_PI_2} ${M_PI} ${M_PI_2}" />
            <parent link="${jaco_prefix}_6_hand_limb" />
            <child link="${jaco_prefix}_fingers_base_link" />
        </joint>

        <!-- ...........................  -->
        <!--      FINGERS          -->
        <!-- ...........................  -->

        <!-- INDEX -->
        <link name="${jaco_prefix}_7_finger_mount_index">
            <inertial>
                <origin xyz="0 0.00706399246397285 -0.00176078508424846" rpy="0 0 0" />
                <xacro:cyl_inertia mass="${0.006465/finger_mass_divider}" h="0.022" r="0.018" />
            </inertial>
            <visual>
                <origin xyz="0 0 0" rpy="${M_PI_2} 0 ${M_PI_2}" />
                <geometry>
                    <mesh
                        filename="package://manipulacion_pkg/urdf/meshes/jaco_hand/7_finger_mount_index.STL" />
                </geometry>
                <material name="">
                    <color rgba="0.5 0.5 0.5 1" />
                </material>
            </visual>
            <collision>
                <origin xyz="0 0 0" rpy="${M_PI_2} 0 ${M_PI_2}" />
                <geometry>
                    <mesh
                        filename="package://manipulacion_pkg/urdf/meshes/jaco_hand/7_finger_mount_index.STL" />
                </geometry>
            </collision>

        </link>

        <joint name="${jaco_prefix}_finger_mount_index_fixed" type="fixed">
            <xacro:damping_fingers />
            <origin xyz="${f_idx_m_xyz}" rpy="${f_idx_m_rpy}" />
            <parent link="${jaco_prefix}_fingers_base_link" />
            <child link="${jaco_prefix}_7_finger_mount_index" />
            <axis xyz="0 0 0" />
        </joint>
        <link name="${jaco_prefix}_8_finger_index">
            <inertial>
                <origin xyz="-0.0181403689626489 0 0.00272470933850985" rpy="0 0 0" />
                <xacro:cyl_inertia mass="${0.01845/finger_mass_divider}" h="0.06" r="0.0135" />
            </inertial>
            <visual>
                <origin xyz="0 0 0" rpy="${M_PI} ${M_PI_4+M_PI_4/2.0} 0" />
                <geometry>
                    <mesh filename="package://manipulacion_pkg/urdf/meshes/jaco_hand/8_finger_index.STL" />
                </geometry>
                <material name="">
                    <color rgba="0.50 0.50 0.50 1" />
                </material>
            </visual>
            <collision>
                <origin xyz="0 0 0" rpy="${M_PI} ${M_PI_4+M_PI_4/2.0} 0" />
                <geometry>
                    <mesh filename="package://manipulacion_pkg/urdf/meshes/jaco_hand/8_finger_index.STL" />
                </geometry>
            </collision>

        </link>
        <joint name="${jaco_prefix}_finger_joint_0" type="revolute">
            <xacro:damping_fingers />
            <origin xyz="${f_idx_xyz}" rpy="${f_idx_rpy}" />
            <parent link="${jaco_prefix}_fingers_base_link" />
            <child link="${jaco_prefix}_8_finger_index" />
            <axis xyz="0 -1 0" />
            <xacro:default_finger_limits />
        </joint>

        <link name="${jaco_prefix}_9_finger_index_tip">
            <inertial>
                <origin xyz="-0.01340812509202 -4.52693266978291E-07 0.0118561361126153" rpy="0 0 0" />
                <xacro:cyl_inertia mass="${0.0122/finger_mass_divider}" h="0.047" r="0.012" />
            </inertial>
            <visual>
                <origin xyz="0 0 0" rpy="0 ${M_PI_2} ${M_PI}" />
                <geometry>
                    <mesh
                        filename="package://manipulacion_pkg/urdf/meshes/jaco_hand/9_finger_index_tip.STL"
                        scale="${tip_scale_x} ${tip_scale_y} ${tip_scale_z}" />
                </geometry>
                <material name="">
                    <color rgba="0.5 0.5 0.5 1" />
                </material>
            </visual>
            <collision>
                <origin xyz="0 0 0" rpy="0 ${M_PI_2} ${M_PI}" />
                <geometry>
                    <mesh
                        filename="package://manipulacion_pkg/urdf/meshes/jaco_hand/9_finger_index_tip.STL"
                        scale="${tip_scale_x} ${tip_scale_y} ${tip_scale_z}" />
                </geometry>
            </collision>

        </link>
        <joint name="${jaco_prefix}_finger_joint_1" type="fixed">
            <xacro:damping_fingers />
            <origin xyz="0 0 0.0441" rpy="0 0 0" />
            <parent link="${jaco_prefix}_8_finger_index" />
            <child link="${jaco_prefix}_9_finger_index_tip" />
        </joint>
        <!-- THUMB -->
        <link name="${jaco_prefix}_7_finger_mount_thumb">
            <inertial>
                <origin xyz="-2.65251193937339E-07 0.00706398229186052 -0.00176078674955921"
                    rpy="0 0 0" />
                <xacro:cyl_inertia mass="${0.006465/finger_mass_divider}" h="0.022" r="0.018" />
            </inertial>
            <visual>
                <origin xyz="0 0 0" rpy="${M_PI_2} 0 ${M_PI_2}" />
                <geometry>
                    <mesh
                        filename="package://manipulacion_pkg/urdf/meshes/jaco_hand/7_finger_mount_thumb.STL" />
                </geometry>
                <material name="">
                    <color rgba="0.50 0.50 0.50 1" />
                </material>
            </visual>
            <collision>
                <origin xyz="0 0 0" rpy="${M_PI_2} 0 ${M_PI_2}" />
                <geometry>
                    <mesh
                        filename="package://manipulacion_pkg/urdf/meshes/jaco_hand/7_finger_mount_thumb.STL" />
                </geometry>
            </collision>
 
        </link>
        <joint name="${jaco_prefix}_finger_mount_thumb_fixed" type="fixed">
            <xacro:damping_fingers />
            <origin xyz="${f_thb_m_xyz}" rpy="${f_thb_m_rpy}" />
            <parent link="${jaco_prefix}_fingers_base_link" />
            <child link="${jaco_prefix}_7_finger_mount_thumb" />
        </joint>

        <link name="${jaco_prefix}_8_finger_thumb">
            <inertial>
                <origin xyz="-0.0181403317517619 -3.13818432741766E-07 0.00272473343106584"
                    rpy="0 0 0" />
                <xacro:cyl_inertia mass="${0.0184/finger_mass_divider}" h="0.06" r="0.0135" />
            </inertial>
            <visual>
                <origin xyz="0 0 0" rpy="${M_PI} ${M_PI_4+M_PI_4/2.0} 0" />
                <geometry>
                    <mesh filename="package://manipulacion_pkg/urdf/meshes/jaco_hand/8_finger_thumb.STL" />
                </geometry>
                <material name="">
                    <color rgba="0.5 0.5 0.5 1" />
                </material>
            </visual>
            <collision>
                <origin xyz="0 0 0" rpy="${M_PI} ${M_PI_4+M_PI_4/2.0} 0" />
                <geometry>
                    <mesh filename="package://manipulacion_pkg/urdf/meshes/jaco_hand/8_finger_thumb.STL" />
                </geometry>
            </collision>

        </link>
        <joint name="${jaco_prefix}_finger_joint_2" type="revolute">
            <xacro:damping_fingers />
            <origin xyz="${f_thb_xyz}" rpy="${f_thb_rpy}" />
            <parent link="${jaco_prefix}_fingers_base_link" />
            <child link="${jaco_prefix}_8_finger_thumb" />
            <axis xyz="0 -1 0" />
            <xacro:default_finger_limits />
        </joint>

        <link name="${jaco_prefix}_9_finger_thumb_tip">
            <inertial>
                <origin xyz="-0.0134080639046228 -4.56622786070351E-07 0.0118561154422042"
                    rpy="0 0 0" />
                <xacro:cyl_inertia mass="${0.0122/finger_mass_divider}" h="0.047" r="0.012" />
            </inertial>
            <visual>
                <origin xyz="0 0 0" rpy="0 ${M_PI_2} ${M_PI}" />
                <geometry>
                    <mesh
                        filename="package://manipulacion_pkg/urdf/meshes/jaco_hand/9_finger_thumb_tip.STL"
                        scale="${tip_scale_x} ${tip_scale_y} ${tip_scale_z}" />
                </geometry>
                <material name="">
                    <color rgba="0.5 0.5 0.5 1" />
                </material>
            </visual>
            <collision>
                <origin xyz="0 0 0" rpy="0 ${M_PI_2} ${M_PI}" />
                <geometry>
                    <mesh
                        filename="package://manipulacion_pkg/urdf/meshes/jaco_hand/9_finger_thumb_tip.STL"
                        scale="${tip_scale_x} ${tip_scale_y} ${tip_scale_z}" />
                </geometry>
            </collision>

        </link>
        <joint name="${jaco_prefix}_finger_joint_3" type="fixed">
            <xacro:damping_fingers />
            <origin xyz="0 0 0.0441" rpy="0 0 0" />
            <parent link="${jaco_prefix}_8_finger_thumb" />
            <child link="${jaco_prefix}_9_finger_thumb_tip" />
        </joint>

        <!-- PINKY -->
        <link name="${jaco_prefix}_7_finger_mount_pinkie">
            <inertial>
                <origin xyz="0 0.00706399455294665 -0.00176077690193762" rpy="0 0 0" />
                <xacro:cyl_inertia mass="${0.00646/finger_mass_divider}" h="0.022" r="0.018" />
            </inertial>
            <visual>
                <origin xyz="0 0 0" rpy="${M_PI_2} 0 ${M_PI_2}" />
                <geometry>
                    <mesh
                        filename="package://manipulacion_pkg/urdf/meshes/jaco_hand/7_finger_mount_pinkie.STL" />
                </geometry>
                <material name="">
                    <color rgba="0.5 0.5 0.5 1" />
                </material>
            </visual>
            <collision>
                <origin xyz="0 0 0" rpy="${M_PI_2} 0 ${M_PI_2}" />
                <geometry>
                    <mesh
                        filename="package://manipulacion_pkg/urdf/meshes/jaco_hand/7_finger_mount_pinkie.STL" />
                </geometry>
            </collision>

        </link>
        <joint name="${jaco_prefix}_finger_mount_pinkie_fixed" type="fixed">
            <xacro:damping_fingers />
            <origin xyz="${f_pnk_m_xyz}" rpy="${f_pnk_m_rpy}" />
            <parent link="${jaco_prefix}_fingers_base_link" />
            <child link="${jaco_prefix}_7_finger_mount_pinkie" />
        </joint>

        <link name="${jaco_prefix}_8_finger_pinkie">
            <inertial>
                <origin xyz="-0.0181404164708055 -2.87009015777565E-07 0.00272467774606585"
                    rpy="0 0 0" />
                <xacro:cyl_inertia mass="${0.01845/finger_mass_divider}" h="0.06" r="0.0135" />
            </inertial>
            <visual>
                <origin xyz="0 0 0" rpy="${M_PI} ${M_PI_4+M_PI_4/2.0} 0" />
                <geometry>
                    <mesh filename="package://manipulacion_pkg/urdf/meshes/jaco_hand/8_finger_pinkie.STL" />
                </geometry>
                <material name="">
                    <color rgba="0.5 0.5 0.5 1" />
                </material>
            </visual>
            <collision>
                <origin xyz="0 0 0" rpy="${M_PI} ${M_PI_4+M_PI_4/2.0} 0" />
                <geometry>
                    <mesh filename="package://manipulacion_pkg/urdf/meshes/jaco_hand/8_finger_pinkie.STL" />
                </geometry>
            </collision>
        </link>
        <joint name="${jaco_prefix}_finger_joint_4" type="revolute">
            <xacro:damping_fingers />
            <origin xyz="${f_pnk_xyz}" rpy="${f_pnk_rpy}" />
            <parent link="${jaco_prefix}_fingers_base_link" />
            <child link="${jaco_prefix}_8_finger_pinkie" />
            <axis xyz="0 -1 0" />
            <xacro:default_finger_limits />
        </joint>
        <link name="${jaco_prefix}_9_finger_pinkie_tip">
            <inertial>
                <origin xyz="-0.0134 0 0.01185" rpy="0 0 0" />
                <xacro:cyl_inertia mass="${0.0122/finger_mass_divider}" h="0.047" r="0.012" />
            </inertial>
            <visual>
                <origin xyz="0 0 0" rpy="0 ${M_PI_2} ${M_PI}" />
                <geometry>
                    <mesh
                        filename="package://manipulacion_pkg/urdf/meshes/jaco_hand/9_finger_pinkie_tip.STL"
                        scale="${tip_scale_x} ${tip_scale_y} ${tip_scale_z}" />
                </geometry>
                <material name="">
                    <color rgba="0.5 0.5 0.5 1" />
                </material>
            </visual>
            <collision>
                <origin xyz="0 0 0" rpy="0 ${M_PI_2} ${M_PI}" />
                <geometry>
                    <mesh
                        filename="package://manipulacion_pkg/urdf/meshes/jaco_hand/9_finger_pinkie_tip.STL"
                        scale="${tip_scale_x} ${tip_scale_y} ${tip_scale_z}" />
                </geometry>
            </collision>

        </link>
        <joint name="${jaco_prefix}_finger_joint_5" type="fixed">
            <xacro:damping_fingers />
            <origin xyz="0 0 0.0441" rpy="0 0 0" />
            <parent link="${jaco_prefix}_8_finger_pinkie" />
            <child link="${jaco_prefix}_9_finger_pinkie_tip" />
        </joint>

        <transmission name="${jaco_prefix}_finger_joint_0_pos_transmission">
            <type>transmission_interface/SimpleTransmission</type>
            <joint name="${jaco_prefix}_finger_joint_0">
                <hardwareInterface>EffortJointInterface</hardwareInterface>
            </joint>
            <actuator name="${jaco_prefix}_finger_joint_0_effort_motor">
                <hardwareInterface>EffortJointInterface</hardwareInterface>
                <mechanicalReduction>1</mechanicalReduction>
            </actuator>
        </transmission>

        <transmission name="${jaco_prefix}_finger_joint_2_pos_transmission">
            <type>transmission_interface/SimpleTransmission</type>
            <joint name="${jaco_prefix}_finger_joint_2">
                <hardwareInterface>EffortJointInterface</hardwareInterface>
            </joint>
            <actuator name="${jaco_prefix}_finger_joint_2_effort_motor">
                <hardwareInterface>EffortJointInterface</hardwareInterface>
                <mechanicalReduction>1</mechanicalReduction>
            </actuator>
        </transmission>

        <transmission name="${jaco_prefix}_finger_joint_4_pos_transmission">
            <type>transmission_interface/SimpleTransmission</type>
            <joint name="${jaco_prefix}_finger_joint_4">
                <hardwareInterface>EffortJointInterface</hardwareInterface>
            </joint>
            <actuator name="${jaco_prefix}_finger_joint_4_effort_motor">
                <hardwareInterface>EffortJointInterface</hardwareInterface>
                <mechanicalReduction>1</mechanicalReduction>
            </actuator>
        </transmission>

        <gazebo reference="${jaco_prefix}_7_finger_mount_index">
            <mu1>0.7</mu1> <!-- Coefficient of friction in one direction -->
            <mu2>0.7</mu2> <!-- Coefficient of friction in the other direction -->
            <kp>1e5</kp> <!-- Contact stiffness -->
            <kd>1</kd> <!-- Contact damping -->
            <minDepth>0.01</minDepth> <!-- Minimum depth before contact is considered -->
            <maxVel>0.1</maxVel> <!-- Maximum contact velocity -->
        </gazebo>

        <gazebo reference="${jaco_prefix}_8_finger_index">
            <mu1>0.7</mu1> <!-- Coefficient of friction in one direction -->
            <mu2>0.7</mu2> <!-- Coefficient of friction in the other direction -->
            <kp>1e5</kp> <!-- Contact stiffness -->
            <kd>1</kd> <!-- Contact damping -->
            <minDepth>0.01</minDepth> <!-- Minimum depth before contact is considered -->
            <maxVel>0.1</maxVel> <!-- Maximum contact velocity -->
        </gazebo>

        <gazebo reference="${jaco_prefix}_9_finger_index_tip">
            <mu1>0.7</mu1> <!-- Coefficient of friction in one direction -->
            <mu2>0.7</mu2> <!-- Coefficient of friction in the other direction -->
            <kp>1e5</kp> <!-- Contact stiffness -->
            <kd>1</kd> <!-- Contact damping -->
            <minDepth>0.01</minDepth> <!-- Minimum depth before contact is considered -->
            <maxVel>0.1</maxVel> <!-- Maximum contact velocity -->
        </gazebo>

        <gazebo reference="${jaco_prefix}_7_finger_mount_thumb">
            <mu1>0.7</mu1> <!-- Coefficient of friction in one direction -->
            <mu2>0.7</mu2> <!-- Coefficient of friction in the other direction -->
            <kp>1e5</kp> <!-- Contact stiffness -->
            <kd>1</kd> <!-- Contact damping -->
            <minDepth>0.01</minDepth> <!-- Minimum depth before contact is considered -->
            <maxVel>0.1</maxVel> <!-- Maximum contact velocity -->
        </gazebo>

        <gazebo reference="${jaco_prefix}_8_finger_thumb">
            <mu1>0.7</mu1> <!-- Coefficient of friction in one direction -->
            <mu2>0.7</mu2> <!-- Coefficient of friction in the other direction -->
            <kp>1e5</kp> <!-- Contact stiffness -->
            <kd>1</kd> <!-- Contact damping -->
            <minDepth>0.01</minDepth> <!-- Minimum depth before contact is considered -->
            <maxVel>0.1</maxVel> <!-- Maximum contact velocity -->
        </gazebo>

        <gazebo reference="${jaco_prefix}_9_finger_thumb_tip">
            <mu1>0.7</mu1> <!-- Coefficient of friction in one direction -->
            <mu2>0.7</mu2> <!-- Coefficient of friction in the other direction -->
            <kp>1e5</kp> <!-- Contact stiffness -->
            <kd>1</kd> <!-- Contact damping -->
            <minDepth>0.01</minDepth> <!-- Minimum depth before contact is considered -->
            <maxVel>0.1</maxVel> <!-- Maximum contact velocity -->
        </gazebo>

        <gazebo reference="${jaco_prefix}_7_finger_mount_pinkie">
            <mu1>0.7</mu1> <!-- Coefficient of friction in one direction -->
            <mu2>0.7</mu2> <!-- Coefficient of friction in the other direction -->
            <kp>1e5</kp> <!-- Contact stiffness -->
            <kd>1</kd> <!-- Contact damping -->
            <minDepth>0.01</minDepth> <!-- Minimum depth before contact is considered -->
            <maxVel>0.1</maxVel> <!-- Maximum contact velocity -->
        </gazebo>

        <gazebo reference="${jaco_prefix}_8_finger_pinkie">
            <mu1>0.7</mu1> <!-- Coefficient of friction in one direction -->
            <mu2>0.7</mu2> <!-- Coefficient of friction in the other direction -->
            <kp>1e5</kp> <!-- Contact stiffness -->
            <kd>1</kd> <!-- Contact damping -->
            <minDepth>0.01</minDepth> <!-- Minimum depth before contact is considered -->
            <maxVel>0.1</maxVel> <!-- Maximum contact velocity -->
        </gazebo>

        <gazebo reference="${jaco_prefix}_9_finger_pinkie_tip">
            <mu1>0.7</mu1> <!-- Coefficient of friction in one direction -->
            <mu2>0.7</mu2> <!-- Coefficient of friction in the other direction -->
            <kp>1e5</kp> <!-- Contact stiffness -->
            <kd>1</kd> <!-- Contact damping -->
            <minDepth>0.01</minDepth> <!-- Minimum depth before contact is considered -->
            <maxVel>0.1</maxVel> <!-- Maximum contact velocity -->
        </gazebo>

        
        <gazebo>
            <plugin name="gazebo_grasp_fix" filename="libgazebo_grasp_fix.so">
                 <arm>
                    <xacro:if value="${floating_gripper}">
                        <arm_name>gripper</arm_name>
                        <palm_link>tool0</palm_link>
                    </xacro:if>
                    <xacro:unless value="${floating_gripper}">
                        <arm_name>ur10</arm_name>
                        <palm_link>wrist_3_link</palm_link>
                    </xacro:unless>
                    <gripper_link> ${jaco_prefix}_8_finger_index </gripper_link>
                    <gripper_link> ${jaco_prefix}_8_finger_thumb </gripper_link>
                    <gripper_link> ${jaco_prefix}_8_finger_pinkie </gripper_link>
                 </arm>
                <forces_angle_tolerance>100</forces_angle_tolerance>
                <update_rate>10</update_rate>
                <grip_count_threshold>2</grip_count_threshold>
                <max_grip_count>8</max_grip_count>
                <release_tolerance>0.005</release_tolerance>
                <disable_collisions_on_attach>false</disable_collisions_on_attach>
                <contact_topic>__default_topic__</contact_topic>
             </plugin>
         </gazebo>

        <!-- if not activate gravity, deactivate it -->
        <xacro:unless value="${activate_gravity}">
            <gazebo reference="${jaco_prefix}_6_hand_limb">
                <gravity>0</gravity>
            </gazebo>

            <gazebo reference="${jaco_prefix}_8_finger_index">
                <gravity>0</gravity>
            </gazebo>

            <gazebo reference="${jaco_prefix}_8_finger_thumb">
                <gravity>0</gravity>
            </gazebo>

            <gazebo reference="${jaco_prefix}_8_finger_pinkie">
                <gravity>0</gravity>
            </gazebo>
        </xacro:unless>
        

    </xacro:macro>

</robot>