<?xml version="1.0"?>
<robot xmlns:xacro="http://wiki.ros.org/xacro" name="jaco_hand">
  
  <link name="jaco_6_hand_limb">
    <visual>
      <origin xyz="0 0 0" rpy="0 0 0" />
      <geometry>
        <mesh filename="package://manipulacion_pkg/urdf/meshes/jaco_hand/6_hand_limb.STL"
          scale="1 1 1" />
      </geometry>
      <material name="">
        <color rgba="0.1 0.1 0.1 1" />
      </material>
    </visual>
    <collision>
      <origin xyz="0 0 0" rpy="0 0 0" />
      <geometry>
        <mesh filename="package://manipulacion_pkg/urdf/meshes/jaco_hand/6_hand_limb.STL"
          scale="1 1 1" />
      </geometry>
    </collision>
  </link>

  <link name="tool0">
  </link>

  <joint name="hand_joint" type="fixed">
    <origin xyz="0 0.0 0" rpy=" 0 0 0" />
    <parent link="tool0" />
    <child link="jaco_6_hand_limb" />
  </joint>


  <link name="jaco_fingers_base_link">
  </link>

  <!-- this joint is only to align the coordinate system with the kinova specification frame -->
  <joint name="fingers_base_joint" type="fixed">
    <origin xyz="0 0 0" rpy="-1.5707963267948966 3.141592653589793 1.5707963267948966" />
    <parent link="jaco_6_hand_limb" />
    <child link="jaco_fingers_base_link" />
  </joint>

  <link name="jaco_7_finger_mount_index">
    <visual>
      <origin xyz="0 0 0" rpy="1.5707963267948966 0 1.5707963267948966" />
      <geometry>
        <mesh
          filename="package://manipulacion_pkg/urdf/meshes/jaco_hand/7_finger_mount_index.STL" />
      </geometry>
      <material name="">
        <color rgba="1.0 1.0 1.0 1" />
      </material>
    </visual>
    <collision>
      <origin xyz="0 0 0" rpy="1.5707963267948966 0 1.5707963267948966" />
      <geometry>
        <mesh
          filename="package://manipulacion_pkg/urdf/meshes/jaco_hand/7_finger_mount_index.STL" />
      </geometry>
    </collision>
  </link>

  <joint name="jaco_finger_mount_index_fixed" type="fixed">
    <origin xyz="-0.034  0.022 0.095" rpy="0 -0.2293 -0.191986" />
    <parent link="jaco_fingers_base_link" />
    <child link="jaco_7_finger_mount_index" />
    <axis xyz="0 0 0" />
  </joint>

  <link name="jaco_8_finger_index">
    <visual>
        <origin xyz="0 0 0" rpy="3.141592653589793 1.1780972450961724 0" />
        <geometry>
            <mesh filename="package://manipulacion_pkg/urdf/meshes/jaco_hand/8_finger_index.STL" />
        </geometry>
        <material name="">
            <color rgba="1.0 1.0 1.0 1" />
        </material>
    </visual>
    <collision>
        <origin xyz="0 0 0" rpy="3.141592653589793 1.1780972450961724 0"/>
        <geometry>
            <mesh filename="package://manipulacion_pkg/urdf/meshes/jaco_hand/8_finger_index.STL" />
        </geometry>
    </collision>
  </link>

  <joint name="finger_joint_0" type="revolute">
    <origin xyz="-0.034  0.022 0.095" rpy="0 -0.2293 -0.191986" />
    <parent link="jaco_fingers_base_link" />
    <child link="jaco_8_finger_index" />
    <axis xyz="0 1 0" />
    <limit lower="-1.005" upper="0.1" effort="1.5" velocity="0.2" />

</joint>


<link name="jaco_9_finger_index_tip">
  <visual>
      <origin xyz="0 0 0" rpy="0 1.5707963267948966 3.141592653589793" />
      <geometry>
          <mesh
              filename="package://manipulacion_pkg/urdf/meshes/jaco_hand/9_finger_index_tip.STL"
              scale="1 1 1" />
      </geometry>
      <material name="">
          <color rgba="1.0 1.0 1.0 1" />
      </material>
  </visual>
  <collision>
      <origin xyz="0 0 0" rpy="0 1.5707963267948966 3.141592653589793" />
      <geometry>
          <mesh
              filename="package://manipulacion_pkg/urdf/meshes/jaco_hand/9_finger_index_tip.STL"
              scale="1 1 1" />
      </geometry>
  </collision>
</link>

<joint name="finger_joint_1" type="fixed">
  <origin xyz="0 0 0.0441" rpy="0 0 0" />
  <parent link="jaco_8_finger_index" />
  <child link="jaco_9_finger_index_tip" />
</joint>

<!-- THUMB -->
<link name="jaco_7_finger_mount_thumb">
  <visual>
      <origin xyz="0 0 0" rpy="1.5707963267948966 0 1.5707963267948966" />
      <geometry>
          <mesh
              filename="package://manipulacion_pkg/urdf/meshes/jaco_hand/7_finger_mount_thumb.STL" />
      </geometry>
      <material name="">
          <color rgba="1.0 1.0 1.0 1" />
      </material>
  </visual>
  <collision>
      <origin xyz="0 0 0" rpy="1.5707963267948966 0 1.5707963267948966" />
      <geometry>
          <mesh
              filename="package://manipulacion_pkg/urdf/meshes/jaco_hand/7_finger_mount_thumb.STL" />
      </geometry>
  </collision>
</link>

<joint name="finger_mount_thumb_fixed" type="fixed">
  <origin xyz="0.037  0.001  0.095" rpy="0 -0.2658 2.9147006535897932" />
  <parent link="jaco_fingers_base_link" />
  <child link="jaco_7_finger_mount_thumb" />
</joint>

<link name="jaco_8_finger_thumb">
  <visual>
      <origin xyz="0 0 0" rpy="3.141592653589793 1.1780972450961724 0" />
      <geometry>
          <mesh filename="package://manipulacion_pkg/urdf/meshes/jaco_hand/8_finger_thumb.STL" />
      </geometry>
      <material name="">
          <color rgba="1.0 1.0 1.0 1" />
      </material>
  </visual>
  <collision>
      <origin xyz="0 0 0" rpy="3.141592653589793 1.1780972450961724 0" />
      <geometry>
          <mesh filename="package://manipulacion_pkg/urdf/meshes/jaco_hand/8_finger_thumb.STL" />
      </geometry>
  </collision>
</link>

<joint name="finger_joint_2" type="revolute">
  <origin xyz="0.0319  0.003  0.11" rpy="0 -0.37 2.9147006535897932" />
  <parent link="jaco_fingers_base_link" />
  <child link="jaco_8_finger_thumb" />
  <axis xyz="0 1 0" />
  <limit lower="-1.005" upper="0.1" effort="1.5" velocity="0.2" />

</joint>

<link name="jaco_9_finger_thumb_tip">
  <visual>
      <origin xyz="0 0 0" rpy="0 1.5707963267948966 3.141592653589793" />
      <geometry>
          <mesh
              filename="package://manipulacion_pkg/urdf/meshes/jaco_hand/9_finger_thumb_tip.STL"
              scale="1 1 1" />
      </geometry>
      <material name="">
          <color rgba="1.0 1.0 1.0 1" />
      </material>
  </visual>
  <collision>
      <origin xyz="0 0 0" rpy="0 1.5707963267948966 3.141592653589793" />
      <geometry>
          <mesh
              filename="package://manipulacion_pkg/urdf/meshes/jaco_hand/9_finger_thumb_tip.STL"
              scale="1 1 1" />
      </geometry>
  </collision>
</link>

<joint name="finger_joint_3" type="fixed">
  <origin xyz="0 0 0.0441" rpy="0 0 0" />
  <parent link="jaco_8_finger_thumb" />
  <child link="jaco_9_finger_thumb_tip" />
</joint>

<!-- PINKY -->
<link name="jaco_7_finger_mount_pinkie">
  <visual>
      <origin xyz="0 0 0" rpy="1.5707963267948966 0 1.5707963267948966" />
      <geometry>
          <mesh
              filename="package://manipulacion_pkg/urdf/meshes/jaco_hand/7_finger_mount_pinkie.STL" />
      </geometry>
      <material name="">
          <color rgba="1.0 1.0 1.0 1" />
      </material>
  </visual>
  <collision>
      <origin xyz="0 0 0" rpy="1.5707963267948966 0 1.5707963267948966" />
      <geometry>
          <mesh
              filename="package://manipulacion_pkg/urdf/meshes/jaco_hand/7_finger_mount_pinkie.STL" />
      </geometry>
  </collision>
</link>

<joint name="finger_mount_pinkie_fixed" type="fixed">
  <origin xyz="-0.034 -0.022 0.095" rpy="0 -0.2293 0.191986" />
  <parent link="jaco_fingers_base_link" />
  <child link="jaco_7_finger_mount_pinkie" />
</joint>

<link name="jaco_8_finger_pinkie">
  <visual>
      <origin xyz="0 0 0" rpy="3.141592653589793 1.1780972450961724 0" />
      <geometry>
          <mesh filename="package://manipulacion_pkg/urdf/meshes/jaco_hand/8_finger_pinkie.STL" />
      </geometry>
      <material name="">
          <color rgba="1.0 1.0 1.0 1" />
      </material>
  </visual>
  <collision>
      <origin xyz="0 0 0" rpy="3.141592653589793 1.1780972450961724 0" />
      <geometry>
          <mesh filename="package://manipulacion_pkg/urdf/meshes/jaco_hand/8_finger_pinkie.STL" />
      </geometry>
  </collision>
</link>

<joint name="finger_joint_4" type="revolute">
  <origin xyz="-0.0276 -0.0204 0.11" rpy="0 -0.34 0.191986" />
  <parent link="jaco_fingers_base_link" />
  <child link="jaco_8_finger_pinkie" />
  <axis xyz="0 1 0" />
  <limit lower="-1.005" upper="0.1" effort="1.5" velocity="0.2" />

</joint>

<link name="jaco_9_finger_pinkie_tip">
  <visual>
      <origin xyz="0 0 0" rpy="0 1.5707963267948966 3.141592653589793" />
      <geometry>
          <mesh
              filename="package://manipulacion_pkg/urdf/meshes/jaco_hand/9_finger_pinkie_tip.STL"
              scale="1 1 1" />
      </geometry>
      <material name="">
          <color rgba="1.0 1.0 1.0 1" />
      </material>
  </visual>
  <collision>
      <origin xyz="0 0 0" rpy="0 1.5707963267948966 3.141592653589793" />
      <geometry>
          <mesh
              filename="package://manipulacion_pkg/urdf/meshes/jaco_hand/9_finger_pinkie_tip.STL"
              scale="1 1 1" />
      </geometry>
  </collision>
</link>

<joint name="finger_joint_5" type="fixed">
  <origin xyz="0 0 0.0441" rpy="0 0 0" />
  <parent link="jaco_8_finger_pinkie" />
  <child link="jaco_9_finger_pinkie_tip" />
</joint>



</robot>