<robot xmlns:xacro="http://ros.org/wiki/xacro">
  <xacro:macro name="robotiq_3f_hand" params="parent mass_divider activate_gravity floating_gripper finger_mass_divider *origin prefix:=robotic-3f">
    <joint name="hand_joint" type="fixed">
      <xacro:insert_block name="origin" />
      <parent link="${parent}" />
      <child link="${prefix}palm" />
    </joint>

    <xacro:include filename="$(find manipulacion_pkg)/urdf/robotiq-3f-gripper_finger_articulated_macro.xacro" />
    <xacro:robotiq-3f-gripper_finger_articulated prefix="${prefix}2_finger_1_"/>
    <xacro:robotiq-3f-gripper_finger_articulated prefix="${prefix}3_finger_2_"/>
    <xacro:robotiq-3f-gripper_finger_articulated prefix="${prefix}1_finger_middle_"/>
		<link name="${prefix}palm">
			<visual>
				<geometry>
          <mesh filename="package://manipulacion_pkg/urdf/meshes/robotiq_hand/visual/palm.dae" />
				</geometry>
				<material name="gray">
					<color rgba="0.2 0.2 0.2 1"/>
				</material>
			</visual>
			<collision>
				<geometry>
          <mesh filename="package://manipulacion_pkg/urdf/meshes/robotiq_hand/collision/palm.STL" />
				</geometry>
				<material name="yellow">
					<color rgba="0 1 1 1"/>
				</material>
			</collision>
		</link>

		<!-- end of link list -->
		<!-- joint list -->
		<joint name="${prefix}1_palm_finger_middle_joint" type="fixed">
			<parent link="${prefix}palm"/>
			<child link="${prefix}1_finger_middle_link_0"/>
			<axis xyz="0 0 1"/>
			<origin xyz="0.0455 0.0214 0" rpy="0 0 1.57"/>
		</joint>

		<joint name="${prefix}2_1_palm_finger_1_joint" type="revolute">
			<parent link="${prefix}palm"/>
			<child link="${prefix}2_finger_1_link_0"/>
			<axis xyz="0 1 0"/>
			<origin xyz="-0.0455 0.0214 0.036" rpy="0 3.1416 -1.57"/>
			<limit lower="-0.1784" upper="0.192" effort="100" velocity="10"/>
      <damping>1</damping>
		</joint>

		<joint name="${prefix}3_1_palm_finger_2_joint" type="revolute">
			<parent link="${prefix}palm"/>
			<child link="${prefix}3_finger_2_link_0"/>
			<axis xyz="0 1 0"/>
			<origin xyz="-0.0455 0.0214 -0.036" rpy="0 3.1416 -1.57"/>
			<limit lower="-0.192" upper="0.1784" effort="100" velocity="10"/>
      <damping>1</damping>      <damping>1</damping>

		</joint>


    <transmission name="trans_7_0">
      <type>transmission_interface/SimpleTransmission</type>
      <joint name="${prefix}2_1_palm_finger_1_joint">
        <hardwareInterface>hardware_interface/EffortJointInterface</hardwareInterface>
      </joint>
      <actuator name="motor_7_0">
        <hardwareInterface>hardware_interface/EffortJointInterface</hardwareInterface>
        <mechanicalReduction>1</mechanicalReduction>
      </actuator>
    </transmission>
    <transmission name="trans_7_1">
      <type>transmission_interface/SimpleTransmission</type>
      <joint name="${prefix}2_finger_1_joint_1">
        <hardwareInterface>hardware_interface/EffortJointInterface</hardwareInterface>
      </joint>
      <actuator name="motor_7_1">
        <hardwareInterface>hardware_interface/EffortJointInterface</hardwareInterface>
        <mechanicalReduction>1</mechanicalReduction>
      </actuator>
    </transmission>
    <transmission name="trans_7_2">
      <type>transmission_interface/SimpleTransmission</type>
      <joint name="${prefix}2_finger_1_joint_2">
        <hardwareInterface>hardware_interface/EffortJointInterface</hardwareInterface>
      </joint>
      <actuator name="motor_7_2">
        <hardwareInterface>hardware_interface/EffortJointInterface</hardwareInterface>
        <mechanicalReduction>1</mechanicalReduction>
      </actuator>
    </transmission>
    <transmission name="trans_7_3">
      <type>transmission_interface/SimpleTransmission</type>
      <joint name="${prefix}2_finger_1_joint_3">
        <hardwareInterface>hardware_interface/EffortJointInterface</hardwareInterface>
      </joint>
      <actuator name="motor_7_3">
        <hardwareInterface>hardware_interface/EffortJointInterface</hardwareInterface>
        <mechanicalReduction>1</mechanicalReduction>
      </actuator>
    </transmission>
    <transmission name="trans_8_0">
      <type>transmission_interface/SimpleTransmission</type>
      <joint name="${prefix}3_1_palm_finger_2_joint">
        <hardwareInterface>hardware_interface/EffortJointInterface</hardwareInterface>
      </joint>
      <actuator name="motor_8_0">
        <hardwareInterface>hardware_interface/EffortJointInterface</hardwareInterface>
        <mechanicalReduction>1</mechanicalReduction>
      </actuator>
    </transmission>
    <transmission name="trans_8_1">
      <type>transmission_interface/SimpleTransmission</type>
      <joint name="${prefix}3_finger_2_joint_1">
        <hardwareInterface>hardware_interface/EffortJointInterface</hardwareInterface>
      </joint>
      <actuator name="motor_8_1">
        <hardwareInterface>hardware_interface/EffortJointInterface</hardwareInterface>
        <mechanicalReduction>1</mechanicalReduction>
      </actuator>
    </transmission>
    <transmission name="trans_8_2">
      <type>transmission_interface/SimpleTransmission</type>
      <joint name="${prefix}3_finger_2_joint_2">
        <hardwareInterface>hardware_interface/EffortJointInterface</hardwareInterface>
      </joint>
      <actuator name="motor_8_2">
        <hardwareInterface>hardware_interface/EffortJointInterface</hardwareInterface>
        <mechanicalReduction>1</mechanicalReduction>
      </actuator>
    </transmission>
    <transmission name="trans_8_3">
      <type>transmission_interface/SimpleTransmission</type>
      <joint name="${prefix}3_finger_2_joint_3">
        <hardwareInterface>hardware_interface/EffortJointInterface</hardwareInterface>
      </joint>
      <actuator name="motor_8_3">
        <hardwareInterface>hardware_interface/EffortJointInterface</hardwareInterface>
        <mechanicalReduction>1</mechanicalReduction>
      </actuator>
    </transmission>
    <transmission name="trans_9_1">
      <type>transmission_interface/SimpleTransmission</type>
      <joint name="${prefix}1_finger_middle_joint_1">
        <hardwareInterface>hardware_interface/EffortJointInterface</hardwareInterface>
      </joint>
      <actuator name="motor_9_1">
        <hardwareInterface>hardware_interface/EffortJointInterface</hardwareInterface>
        <mechanicalReduction>1</mechanicalReduction>
      </actuator>
    </transmission>
    <transmission name="trans_9_2">
      <type>transmission_interface/SimpleTransmission</type>
      <joint name="${prefix}1_finger_middle_joint_2">
        <hardwareInterface>hardware_interface/EffortJointInterface</hardwareInterface>
      </joint>
      <actuator name="motor_9_2">
        <hardwareInterface>hardware_interface/EffortJointInterface</hardwareInterface>
        <mechanicalReduction>1</mechanicalReduction>
      </actuator>
    </transmission>
    <transmission name="trans_9_3">
      <type>transmission_interface/SimpleTransmission</type>
      <joint name="${prefix}1_finger_middle_joint_3">
        <hardwareInterface>hardware_interface/EffortJointInterface</hardwareInterface>
      </joint>
      <actuator name="motor_9_3">
        <hardwareInterface>hardware_interface/EffortJointInterface</hardwareInterface>
        <mechanicalReduction>1</mechanicalReduction>
      </actuator>
    </transmission>

     <gazebo>
            <plugin name="gazebo_grasp_fix" filename="libgazebo_grasp_fix.so">
                 <arm>
                    <xacro:if value="${floating_gripper}">
                        <arm_name>gripper</arm_name>
                        <palm_link>tool0</palm_link>
                    </xacro:if>
                    <xacro:unless value="${floating_gripper}">
                        <arm_name>ur10</arm_name>
                        <palm_link>wrist_3_link</palm_link>
                    </xacro:unless>
                    <gripper_link> ${prefix}1_finger_middle_link_1</gripper_link>
                    <gripper_link> ${prefix}1_finger_middle_link_2 </gripper_link>
                    <gripper_link> ${prefix}1_finger_middle_link_3 </gripper_link>
                    <gripper_link> ${prefix}2_finger_1_link_0 </gripper_link>
                    <gripper_link> ${prefix}2_finger_1_link_1 </gripper_link>
                    <gripper_link> ${prefix}2_finger_1_link_2 </gripper_link>
                    <gripper_link> ${prefix}2_finger_1_link_3 </gripper_link>
                    <gripper_link> ${prefix}3_finger_2_link_0 </gripper_link>
                    <gripper_link> ${prefix}3_finger_2_link_1 </gripper_link>
                    <gripper_link> ${prefix}3_finger_2_link_2 </gripper_link>
                    <gripper_link> ${prefix}3_finger_2_link_3 </gripper_link>
                 </arm>
                <forces_angle_tolerance>100</forces_angle_tolerance>
                <update_rate>10</update_rate>
                <grip_count_threshold>2</grip_count_threshold>
                <max_grip_count>8</max_grip_count>
                <release_tolerance>0.005</release_tolerance>
                <disable_collisions_on_attach>true</disable_collisions_on_attach>
                <contact_topic>__default_topic__</contact_topic>
             </plugin>
        </gazebo>
        
	</xacro:macro>
</robot>