<?xml version="1.0" encoding="UTF-8"?>
<robot xmlns:xacro="http://ros.org/wiki/xacro">
    <!-- Colors -->
    <material name="Schunk/LightGrey">
      <color rgba="0.7 0.7 0.7 1.0"/>
    </material>

    <material name="Schunk/DarkGrey">
      <color rgba="0.4 0.4 0.4 1.0"/>
    </material>

    <material name="Schunk/Black">
      <color rgba="0.0 0.0 0.0 1.0"/>
    </material>

    <material name="Schunk/DarkGolden">
      <color rgba="0.4 0.4 0.3 1.0"/>
    </material>

    <material name="Schunk/Blue">
      <color rgba="0.0 0.0 0.8 1.0"/>
    </material>

    <xacro:macro name="mimic_joint_plugin_gazebo" params="name_prefix parent_joint mimic_joint has_pid:=false multiplier:=1.0 offset:=0 sensitiveness:=0.0 max_effort:=1.0 robot_namespace:=''">
      <gazebo>
        <plugin name="${name_prefix}mimic_joint_plugin" filename="libroboticsgroup_gazebo_mimic_joint_plugin.so">
          <joint>${parent_joint}</joint>
          <mimicJoint>${mimic_joint}</mimicJoint>
          <xacro:if value="${has_pid}">                     <!-- if set to true, PID parameters from "/gazebo_ros_control/pid_gains/${mimic_joint}" are loaded -->
            <hasPID />
          </xacro:if>
          <multiplier>${multiplier}</multiplier>
          <offset>${offset}</offset>
          <sensitiveness>${sensitiveness}</sensitiveness>   <!-- if absolute difference between setpoint and process value is below this threshold, do nothing; 0.0 = disable [rad] -->
          <maxEffort>${max_effort}</maxEffort>              <!-- only taken into account if has_pid:=true [Nm] -->
          <xacro:unless value="${robot_namespace == ''}">
            <robotNamespace>${robot_namespace}</robotNamespace>
          </xacro:unless>
        </plugin>
      </gazebo>
    </xacro:macro>

    <!-- MACRO FOR THE ROBOT HAND -->
    <xacro:macro name="schunk_hand"
        params="parent mass_divider activate_gravity floating_gripper finger_mass_divider *origin schunk_prefix:=schunk">

        <!-- ...........................        -->
        <joint name="hand_joint" type="fixed">
            <xacro:insert_block name="origin" />
            <parent link="${parent}" />
            <child link="aux_link" />
        </joint>

        <link name="aux_link"/>
        <joint name="aux_joint" type="fixed">
            <origin xyz="0 0 0.0" rpy="0 0 0"/>
            <parent link="aux_link" />
            <child link="${schunk_prefix}_palm_link" />
        </joint>


         <link name="${schunk_prefix}_palm_link">
          <inertial>
            <origin xyz="0 0 0" rpy="0 0.0 0"/>
            <mass value="1"/>
            <inertia ixx="0.01" ixy="0" ixz="0" iyy="0.01" iyz="0" izz="0.01" />
          </inertial>
          
          <visual>
            <origin xyz="0 0 0" rpy="0 0 0" />
            <geometry>
              <mesh filename="package://manipulacion_pkg/urdf/meshes/schunk_hand/palm.stl" />
            </geometry>
            <material name="Schunk/LightGrey" />
          </visual>
          
          <collision>
            <origin xyz="0 0 0" rpy="0 0 0" />
            <geometry>
              <mesh filename="package://manipulacion_pkg/urdf/meshes/schunk_hand/palm.stl"/>
            </geometry>
          </collision>
        </link>
        
        <joint name="${schunk_prefix}_grasp_joint" type="fixed" >
          <origin xyz="0 0 0.15" rpy="0 0 0"/>
          <parent link="${schunk_prefix}_palm_link" />
          <child link="${schunk_prefix}_grasp_link" />
        </joint>

        <link name="${schunk_prefix}_grasp_link"/>

        <!-- tip link -->
        <joint name="${schunk_prefix}_tip_joint" type="fixed" >
          <origin xyz="0 0 0.22" rpy="0 0 0"/>
          <parent link="${schunk_prefix}_palm_link" />
          <child link="${schunk_prefix}_tip_link" />
        </joint>

        <link name="${schunk_prefix}_tip_link"/>

        <!-- finger1 -->
        <!-- joint between sdh_palm_link and sdh_finger_11_link -->
        <joint name="${schunk_prefix}_11_knuckle_joint" type="revolute">
          <origin xyz="0.01905 0.033 0.0745" rpy="0 0 3.14159265" />
          <parent link="${schunk_prefix}_palm_link"/>
          <child link="${schunk_prefix}_finger_11_link"/>
          <axis xyz="0 0 1" />
          <dynamics damping="1" />
          <limit effort="100" lower="0" upper="1.570796327" velocity="5"/>
        </joint>

        <link name="${schunk_prefix}_finger_11_link">
          <inertial>
            <origin xyz="0 0 0" rpy="0 0 0"/>
            <mass value="0.1"/>
            <inertia ixx="0.01" ixy="0" ixz="0" iyy="0.01" iyz="0" izz="0.01" />
          </inertial>
          
          <visual>
            <origin xyz="0 0 0" rpy="0 0 0" />
            <geometry>
              <mesh filename="package://manipulacion_pkg/urdf/meshes/schunk_hand/knuckle.stl" />
            </geometry>
            <material name="Schunk/LightGrey" />
          </visual>
          
          <collision>
            <origin xyz="0 0 0" rpy="0 0 0" />
            <geometry>
            <mesh filename="package://manipulacion_pkg/urdf/meshes/schunk_hand/knuckle.stl"/>
            </geometry>
            <scale>1.05 1.05 1.05</scale>
          </collision>
        </link>

        <!-- joint between sdh_finger_11_link and sdh_finger_12_link -->
        <joint name="${schunk_prefix}_12_finger_joint" type="revolute">
          <origin xyz="0 0 0.0165" rpy="0 0 0" />
          <parent link="${schunk_prefix}_finger_11_link"/>
          <child link="${schunk_prefix}_finger_12_link"/>
          <axis xyz="0 1 0" />
          <dynamics damping="1" />
          <limit effort="100" lower="-1.570796327" upper="1.570796327" velocity="5"/>
        </joint>

        <link name="${schunk_prefix}_finger_12_link">
          <inertial>
            <origin xyz="0 0 0" rpy="0 0 0"/>
            <mass value="0.1"/>
            <inertia ixx="0.01" ixy="0" ixz="0" iyy="0.01" iyz="0" izz="0.01" />
          </inertial>
          
          <visual>
            <origin xyz="0 0 0" rpy="0 0 0" />
            <geometry>
              <mesh filename="package://manipulacion_pkg/urdf/meshes/schunk_hand/finger.stl" />
            </geometry>
          <material name="Schunk/LightGrey" />
          </visual>
          
          <collision>
            <origin xyz="0 0 0" rpy="0 0 0" />
            <geometry>
              <mesh filename="package://manipulacion_pkg/urdf/meshes/schunk_hand/finger.stl"/>
            </geometry>
          </collision>
        </link>

        <!-- joint between sdh_finger_12_link and sdh_finger_13_link -->
        <joint name="${schunk_prefix}_13_finger_joint" type="revolute">
          
          <origin xyz="0 0 0.0865" rpy="0 0 0" />
          <parent link="${schunk_prefix}_finger_12_link"/>
          <child link="${schunk_prefix}_finger_13_link"/>
          <axis xyz="0 1 0" />
          <dynamics damping="1" />
          <limit effort="100" lower="-1.570796327" upper="1.570796327" velocity="5"/>
        </joint>

        <link name="${schunk_prefix}_finger_13_link">
          <inertial>
          <origin xyz="0 0 0" rpy="0 0 0"/>
            <mass value="0.1"/>
            <inertia ixx="0.01" ixy="0" ixz="0" iyy="0.01" iyz="0" izz="0.01" />
          </inertial>
          
          <visual>
            <origin xyz="0 0 0" rpy="0 0 0" />
            <geometry>
              <mesh filename="package://manipulacion_pkg/urdf/meshes/schunk_hand/finger_tip.stl" />
            </geometry>
            <material name="Schunk/LightGrey" />
          </visual>
          
          <collision>
            <origin xyz="0 0 0" rpy="0 0 0" />
            <geometry>
              <mesh filename="package://manipulacion_pkg/urdf/meshes/schunk_hand/finger_tip.stl"/>
            </geometry>
          </collision>
        </link>

        <!-- finger2 -->
        <!-- joint between sdh_palm_link and sdh_finger_21_link -->
        <joint name="${schunk_prefix}_finger_21_joint" type="revolute">
          <origin xyz="0.01905 -0.033 0.0745" rpy="0 0 3.14159265" />
          <parent link="${schunk_prefix}_palm_link"/>
          <child link="${schunk_prefix}_finger_21_link"/>
          <axis xyz="0 0 -1" />
          <dynamics damping="1" />
          <limit effort="100" lower="0" upper="1.570796327" velocity="5"/>
        </joint>

        <xacro:mimic_joint_plugin_gazebo name_prefix="${schunk_prefix}_finger_21_joint"
            parent_joint="${schunk_prefix}_11_knuckle_joint" mimic_joint="${schunk_prefix}_finger_21_joint"
            has_pid="false" multiplier="1.0" max_effort="100.0" />

        <link name="${schunk_prefix}_finger_21_link">
          <inertial>
            <origin xyz="0 0 0" rpy="0 0 0"/>
            <mass value="0.1"/>
            <inertia ixx="0.01" ixy="0" ixz="0" iyy="0.01" iyz="0" izz="0.01" />
          </inertial>
          
          <visual>
            <origin xyz="0 0 0" rpy="0 0 0" />
            <geometry>
              <mesh filename="package://manipulacion_pkg/urdf/meshes/schunk_hand/knuckle.stl" />
            </geometry>
            <material name="Schunk/LightGrey" />
          </visual>
          
          <collision>
            <origin xyz="0 0 0" rpy="0 0 0" />
            <geometry>
              <mesh filename="package://manipulacion_pkg/urdf/meshes/schunk_hand/knuckle.stl"/>
            </geometry>
          </collision>
        </link>

        <!-- joint between sdh_finger_21_link and sdh_finger_22_link -->
        <joint name="${schunk_prefix}_22_finger_joint" type="revolute">
          <origin xyz="0 0 0.0165" rpy="0 0 0" />
          <parent link="${schunk_prefix}_finger_21_link"/>
          <child link="${schunk_prefix}_finger_22_link"/>
          <axis xyz="0 1 0" />
          <dynamics damping="1" />
          <limit effort="100" lower="-1.570796327" upper="1.570796327" velocity="5"/>
        </joint>

        <link name="${schunk_prefix}_finger_22_link">
          <inertial>
            <origin xyz="0 0 0" rpy="0 0 0"/>
            <mass value="0.1"/>
            <inertia ixx="0.01" ixy="0" ixz="0" iyy="0.01" iyz="0" izz="0.01" />
          </inertial>
          
          <visual>
            <origin xyz="0 0 0" rpy="0 0 0" />
            <geometry>
              <mesh filename="package://manipulacion_pkg/urdf/meshes/schunk_hand/finger.stl" />
            </geometry>
            <material name="Schunk/LightGrey" />
          </visual>
          
          <collision>
            <origin xyz="0 0 0" rpy="0 0 0" />
            <geometry>
              <mesh filename="package://manipulacion_pkg/urdf/meshes/schunk_hand/finger.stl"/>
            </geometry>
          </collision>
        </link>

        <!-- joint between sdh_finger_22_link and sdh_finger_23_link -->
        <joint name="${schunk_prefix}_23_finger_joint" type="revolute">
          <origin xyz="0 0 0.0865" rpy="0 0 0" />
          <parent link="${schunk_prefix}_finger_22_link"/>
          <child link="${schunk_prefix}_finger_23_link"/>
          <axis xyz="0 1 0" />
          <dynamics damping="1" />
          <limit effort="100" lower="-1.570796327" upper="1.570796327" velocity="5"/>
        </joint>

        <link name="${schunk_prefix}_finger_23_link">
          <inertial>
            <origin xyz="0 0 0" rpy="0 0 0"/>
            <mass value="0.1"/>
            <inertia ixx="0.01" ixy="0" ixz="0" iyy="0.01" iyz="0" izz="0.01" />
          </inertial>
          
          <visual>
            <origin xyz="0 0 0" rpy="0 0 0" />
            <geometry>
              <mesh filename="package://manipulacion_pkg/urdf/meshes/schunk_hand/finger_tip.stl" />
            </geometry>
            <material name="Schunk/LightGrey" />
          </visual>
          
          <collision>
            <origin xyz="0 0 0" rpy="0 0 0" />
            <geometry>
              <mesh filename="package://manipulacion_pkg/urdf/meshes/schunk_hand/finger_tip.stl"/>
            </geometry>
          </collision>
        </link>

        <!-- thumb -->
        <!-- joint between sdh_palm_link and sdh_thumb_1_link -->
        <joint name="${schunk_prefix}_thumb_1_joint" type="fixed">
          <origin xyz="-0.03811 0 0.0745 " rpy="0 0 0" />
          <parent link="${schunk_prefix}_palm_link"/>
          <child link="${schunk_prefix}_thumb_1_link"/>
        </joint>

        <link name="${schunk_prefix}_thumb_1_link">
          <inertial>
            <origin xyz="0 0 0" rpy="0 0 0"/>
            <mass value="0.1"/>
            <inertia ixx="0.01" ixy="0" ixz="0" iyy="0.01" iyz="0" izz="0.01" />
          </inertial>
          
          <visual>
            <origin xyz="0 0 0" rpy="0 0 0" />
            <geometry>
              <mesh filename="package://manipulacion_pkg/urdf/meshes/schunk_hand/knuckle.stl" />
            </geometry>
            <material name="Schunk/LightGrey" />
          </visual>
          
          <collision>
            <origin xyz="0 0 0" rpy="0 0 0" />
            <geometry>
              <mesh filename="package://manipulacion_pkg/urdf/meshes/schunk_hand/knuckle.stl"/>
            </geometry>
          </collision>
        </link>

        <!-- joint between sdh_thumb_1_link and shd_thumb_2_link -->
        <joint name="${schunk_prefix}_32_thumb_joint" type="revolute">
        <origin xyz="0 0 0.0165" rpy="0 0 0" />
        <parent link="${schunk_prefix}_thumb_1_link"/>
        <child link="${schunk_prefix}_thumb_2_link"/>
        <axis xyz="0 1 0" />
        <dynamics damping="1" />
        <limit effort="100" lower="-1.570796327" upper="1.570796327" velocity="5"/>
        </joint>

        <link name="${schunk_prefix}_thumb_2_link">
          <inertial>
            <origin xyz="0 0 0" rpy="0 0 0"/>
            <mass value="0.1"/>  
            <inertia ixx="0.01" ixy="0" ixz="0" iyy="0.01" iyz="0" izz="0.01" />
          </inertial>
        
          <visual>
            <origin xyz="0 0 0" rpy="0 0 0" />
            <geometry>
              <mesh filename="package://manipulacion_pkg/urdf/meshes/schunk_hand/finger.stl" />
            </geometry>
            <material name="Schunk/LightGrey" />
          </visual>
        
          <collision>
            <origin xyz="0 0 0" rpy="0 0 0" />
            <geometry>
              <mesh filename="package://manipulacion_pkg/urdf/meshes/schunk_hand/finger.stl"/>
            </geometry>
          </collision>
        </link>

        <!-- joint between sdh_thumb_2_link and sdh_thumb_3_link -->
        <joint name="${schunk_prefix}_33_thumb_joint" type="revolute">
          <origin xyz="0 0 0.0865" rpy="0 0 0" />
          <parent link="${schunk_prefix}_thumb_2_link"/>
          <child link="${schunk_prefix}_thumb_3_link"/>
          <axis xyz="0 1 0" />
          <dynamics damping="1" />
          <limit effort="100" lower="-1.570796327" upper="1.570796327" velocity="5"/>
        </joint>

        <link name="${schunk_prefix}_thumb_3_link">
          <inertial>
            <origin xyz="0 0 0" rpy="0 0 0"/>
            <mass value="0.1"/>
            <inertia ixx="0.01" ixy="0" ixz="0" iyy="0.01" iyz="0" izz="0.01" />
          </inertial>
          
          <visual>
            <origin xyz="0 0 0" rpy="0 0 0" />
            <geometry>
              <mesh filename="package://manipulacion_pkg/urdf/meshes/schunk_hand/finger_tip.stl" />
            </geometry>
            <material name="Schunk/LightGrey" />
          </visual>
          
          <collision>
            <origin xyz="0 0 0" rpy="0 0 0" />
            <geometry>
              <mesh filename="package://manipulacion_pkg/urdf/meshes/schunk_hand/finger_tip.stl"/>
            </geometry>
          </collision>
        </link>

        <transmission name="${schunk_prefix}_knuckle_trans">
          <type>transmission_interface/SimpleTransmission</type>
          <joint name="${schunk_prefix}_11_knuckle_joint">
            <hardwareInterface>hardware_interface/EffortJointInterface</hardwareInterface>
          </joint>
          <actuator name="${schunk_prefix}_knuckle_effort_motor">
            <hardwareInterface>hardware_interface/EffortJointInterface</hardwareInterface>
            <mechanicalReduction>1</mechanicalReduction>
          </actuator>
        </transmission>

        <!-- finger1 -->
        <transmission name="${schunk_prefix}_finger_12_trans">
          <type>transmission_interface/SimpleTransmission</type>
          <joint name="${schunk_prefix}_12_finger_joint">
            <hardwareInterface>hardware_interface/EffortJointInterface</hardwareInterface>
          </joint>
          <actuator name="${schunk_prefix}_finger_12_effort_motor">
            <hardwareInterface>hardware_interface/EffortJointInterface</hardwareInterface>
            <mechanicalReduction>1</mechanicalReduction>
          </actuator>
        </transmission>
      
        <transmission name="${schunk_prefix}_finger_13_trans">
          <type>transmission_interface/SimpleTransmission</type>
          <joint name="${schunk_prefix}_13_finger_joint">
            <hardwareInterface>hardware_interface/EffortJointInterface</hardwareInterface>
          </joint>
          <actuator name="${schunk_prefix}_finger_13_effort_motor">
            <hardwareInterface>hardware_interface/EffortJointInterface</hardwareInterface>
            <mechanicalReduction>1</mechanicalReduction>
          </actuator>
        </transmission>
      
        <!-- finger2 -->
        <transmission name="${schunk_prefix}_finger_22_trans">
          <type>transmission_interface/SimpleTransmission</type>
          <joint name="${schunk_prefix}_22_finger_joint">
            <hardwareInterface>hardware_interface/EffortJointInterface</hardwareInterface>
          </joint>
          <actuator name="${schunk_prefix}_finger_22_effort_motor">
            <hardwareInterface>hardware_interface/EffortJointInterface</hardwareInterface>
            <mechanicalReduction>1</mechanicalReduction>
          </actuator>
        </transmission>
      
        <transmission name="${schunk_prefix}_finger_23_trans">
          <type>transmission_interface/SimpleTransmission</type>
          <joint name="${schunk_prefix}_23_finger_joint">
            <hardwareInterface>hardware_interface/EffortJointInterface</hardwareInterface>
          </joint>
          <actuator name="${schunk_prefix}_finger_23_effort_motor">
            <hardwareInterface>hardware_interface/EffortJointInterface</hardwareInterface>
            <mechanicalReduction>1</mechanicalReduction>
          </actuator>
        </transmission>
      
        <!-- thumb -->
        <transmission name="${schunk_prefix}_thumb_2_trans">
          <type>transmission_interface/SimpleTransmission</type>
          <joint name="${schunk_prefix}_32_thumb_joint">
            <hardwareInterface>hardware_interface/EffortJointInterface</hardwareInterface>
          </joint>
          <actuator name="${schunk_prefix}_thumb_2_effort_motor">
            <hardwareInterface>hardware_interface/EffortJointInterface</hardwareInterface>
            <mechanicalReduction>1</mechanicalReduction>
          </actuator>
        </transmission>
      
        <transmission name="${schunk_prefix}_thumb_3_trans">
          <type>transmission_interface/SimpleTransmission</type>
          <joint name="${schunk_prefix}_33_thumb_joint">  
            <hardwareInterface>hardware_interface/EffortJointInterface</hardwareInterface>
          </joint>  
          <actuator name="${schunk_prefix}_thumb_3_effort_motor">
            <hardwareInterface>hardware_interface/EffortJointInterface</hardwareInterface>
            <mechanicalReduction>1</mechanicalReduction>
          </actuator>
        </transmission>

        <gazebo reference="${schunk_prefix}_finger_12_link">
            <mu1>0.7</mu1> <!-- Coefficient of friction in one direction -->
            <mu2>0.7</mu2> <!-- Coefficient of friction in the other direction -->
            <kp>1e5</kp> <!-- Contact stiffness -->
            <kd>1</kd> <!-- Contact damping -->
            <minDepth>0.01</minDepth> <!-- Minimum depth before contact is considered -->
            <maxVel>0.01</maxVel> <!-- Maximum contact velocity -->
        </gazebo>
        <gazebo reference="${schunk_prefix}_finger_13_link">
            <mu1>0.7</mu1> <!-- Coefficient of friction in one direction -->
            <mu2>0.7</mu2> <!-- Coefficient of friction in the other direction -->
            <kp>1e5</kp> <!-- Contact stiffness -->
            <kd>1</kd> <!-- Contact damping -->
            <minDepth>0.01</minDepth> <!-- Minimum depth before contact is considered -->
            <maxVel>0.01</maxVel> <!-- Maximum contact velocity -->
        </gazebo>
        <gazebo reference="${schunk_prefix}_finger_22_link">
            <mu1>0.7</mu1> <!-- Coefficient of friction in one direction -->
            <mu2>0.7</mu2> <!-- Coefficient of friction in the other direction -->
            <kp>1e5</kp> <!-- Contact stiffness -->
            <kd>1</kd> <!-- Contact damping -->
            <minDepth>0.01</minDepth> <!-- Minimum depth before contact is considered -->
            <maxVel>0.01</maxVel> <!-- Maximum contact velocity -->
        </gazebo>
        <gazebo reference="${schunk_prefix}_finger_23_link">
            <mu1>0.7</mu1> <!-- Coefficient of friction in one direction -->
            <mu2>0.7</mu2> <!-- Coefficient of friction in the other direction -->
            <kp>1e5</kp> <!-- Contact stiffness -->
            <kd>1</kd> <!-- Contact damping -->
            <minDepth>0.01</minDepth> <!-- Minimum depth before contact is considered -->
            <maxVel>0.01</maxVel> <!-- Maximum contact velocity -->
        </gazebo>
        <gazebo reference="${schunk_prefix}_thumb_2_link">
            <mu1>0.7</mu1> <!-- Coefficient of friction in one direction -->
            <mu2>0.7</mu2> <!-- Coefficient of friction in the other direction -->
            <kp>1e5</kp> <!-- Contact stiffness -->
            <kd>1</kd> <!-- Contact damping -->
            <minDepth>0.01</minDepth> <!-- Minimum depth before contact is considered -->
            <maxVel>0.01</maxVel> <!-- Maximum contact velocity -->
        </gazebo>
        <gazebo reference="${schunk_prefix}_thumb_3_link">
            <mu1>0.7</mu1> <!-- Coefficient of friction in one direction -->
            <mu2>0.7</mu2> <!-- Coefficient of friction in the other direction -->
            <kp>1e5</kp> <!-- Contact stiffness -->
            <kd>1</kd> <!-- Contact damping -->
            <minDepth>0.01</minDepth> <!-- Minimum depth before contact is considered -->
            <maxVel>0.01</maxVel> <!-- Maximum contact velocity -->
        </gazebo>

        <gazebo>
            <plugin name="gazebo_grasp_fix" filename="libgazebo_grasp_fix.so">
                 <arm>
                    <xacro:if value="${floating_gripper}">
                        <arm_name>gripper</arm_name>
                        <palm_link>tool0</palm_link>
                    </xacro:if>
                    <xacro:unless value="${floating_gripper}">
                        <arm_name>ur10</arm_name>
                        <palm_link>wrist_3_link</palm_link>
                    </xacro:unless>
                    <gripper_link> ${schunk_prefix}_finger_12_link </gripper_link>
                    <gripper_link> ${schunk_prefix}_finger_13_link </gripper_link>
                    <gripper_link> ${schunk_prefix}_finger_22_link </gripper_link>
                    <gripper_link> ${schunk_prefix}_finger_23_link </gripper_link>
                    <gripper_link> ${schunk_prefix}_thumb_2_link </gripper_link>
                    <gripper_link> ${schunk_prefix}_thumb_3_link </gripper_link>
                 </arm>
                <forces_angle_tolerance>100</forces_angle_tolerance>
                <update_rate>10</update_rate>
                <grip_count_threshold>3</grip_count_threshold>
                <max_grip_count>8</max_grip_count>
                <release_tolerance>0.005</release_tolerance>
                <disable_collisions_on_attach>false</disable_collisions_on_attach>
                <contact_topic>__default_topic__</contact_topic>
             </plugin>
        </gazebo>
        <xacro:unless value="${activate_gravity}">
            <gazebo reference="{schunk_prefix}_finger_12_link">
                <gravity>0</gravity>
            </gazebo>

            <gazebo reference="${schunk_prefix}_finger_13_link">
                <gravity>0</gravity>
            </gazebo>

            <gazebo reference="${schunk_prefix}_finger_22_link">
                <gravity>0</gravity>
            </gazebo>

            <gazebo reference="${schunk_prefix}_finger_23_link">
                <gravity>0</gravity>
            </gazebo>
            <gazebo reference="${schunk_prefix}_thumb_2_link">
                <gravity>0</gravity>
            </gazebo>

            <gazebo reference="${schunk_prefix}_thumb_3_link">
                <gravity>0</gravity>
            </gazebo>
        </xacro:unless>
        

    </xacro:macro>

</robot>